<?xml version="1.0"?>
<robot xmlns:xacro="http://www.ros.org/wiki/xacro" name="sensor_camera">
    <xacro:macro name="GeminiPro_camera" params="parent xyz">
        <!-- 摄像头本体：黑色长方体 11.5cm x 1.7cm x 2.2cm -->
        <link name="camera_body_link">
            <inertial>
                <origin xyz="0.0 0.0 0.0" rpy="0.0 0.0 0.0"/>
                <mass value="0.05"/>
                <inertia ixx="0.000057" ixy="0.0" ixz="0.0" iyy="0.000003" iyz="0.0" izz="0.000056"/>
            </inertial>
            <visual>
                <origin xyz="0.0 0.0 0.0" rpy="0.0 0.0 0.0"/>
                <geometry>
                    <box size="0.017 0.115 0.022"/>
                </geometry>
                <material name="black"/>
            </visual>
            <collision>
                <origin xyz="0.0 0.0 0.0" rpy="0.0 0.0 0.0"/>
                <geometry>
                    <box size="0.017 0.115 0.022"/>
                </geometry>
            </collision>
        </link>

        <!-- 相机俯仰link，无实体 -->
        <link name="camera_pitch_link">
            <inertial>
                <origin xyz="0.0 0.0 0.0" rpy="0.0 0.0 0.0"/>
                <mass value="0.0"/>
                <inertia ixx="0.0" ixy="0.0" ixz="0.0" iyy="0.0" iyz="0.0" izz="0.0"/>
            </inertial>
        </link>

        <!-- Revolute joint: parent → camera_pitch_link，绕Y轴旋转0~45度（向前俯仰） -->
        <joint name="camera_base_joint" type="revolute">
            <origin xyz="${xyz}" rpy="0.0 0.0 0.0"/>
            <parent link="${parent}"/>
            <child link="camera_pitch_link"/>
            <axis xyz="0.0 1.0 0.0"/>
            <limit lower="0.0" upper="0.7854" effort="1.0" velocity="1.0"/>
        </joint>

        <!-- Fixed joint: camera_pitch_link → camera_body_link -->
        <joint name="camera_mount_joint" type="fixed">
            <origin xyz="-0.0085 0.0 0.011" rpy="0.0 0.0 0.0"/>
            <parent link="camera_pitch_link"/>
            <child link="camera_body_link"/>
            <axis xyz="0.0 0.0 0.0"/>
        </joint>
    </xacro:macro>
</robot>
