<?xml version="1.0" ?>
<!-- =================================================================================== -->
<!-- |    This document was autogenerated by xacro from src/wuyang_description/urdf/wuyang_ackermann.urdf.xacro | -->
<!-- |    EDITING THIS FILE BY HAND IS NOT RECOMMENDED                                 | -->
<!-- =================================================================================== -->
<robot name="wuyang_ackermann">
  <material name="black">
    <color rgba="0.0 0.0 0.0 1.0"/>
  </material>
  <material name="blue">
    <color rgba="0.2 0.2 0.8 1.0"/>
  </material>
  <material name="sliver">
    <color rgba="0.7 0.7 0.7 1.0"/>
  </material>
  <link name="base_footprint"/>
  <link name="base_link">
    <inertial>
      <origin rpy="0.0 0.0 0.0" xyz="0.0 0.0 0.0"/>
      <mass value="3.0"/>
      <inertia ixx="0.0068" ixy="0.0" ixz="0.0" iyy="0.0213" iyz="0.0" izz="0.0206"/>
    </inertial>
    <visual name="RectangularPrism">
      <origin rpy="0.0 0.0 0.0" xyz="0.0 0.0 0.0"/>
      <geometry>
        <box size="0.265 0.11 0.123"/>
      </geometry>
      <material name="sliver"/>
    </visual>
    <collision>
      <origin rpy="0.0 0.0 0.0" xyz="0.0 0.0 0.0"/>
      <geometry>
        <box size="0.265 0.11 0.123"/>
      </geometry>
    </collision>
  </link>
  <joint name="joint_name" type="fixed">
    <origin rpy="0.0 0.0 0.0" xyz="0.0 0.0 0.0765"/>
    <parent link="base_footprint"/>
    <child link="base_link"/>
    <axis xyz="0.0 0.0 0.0"/>
    <limit effort="0.0" lower="0.0" upper="0.0" velocity="0.0"/>
  </joint>
  <link name="left_front_knuckle">
    <inertial>
      <origin rpy="0.0 0.0 0.0" xyz="0.0 0.0 0.0"/>
      <mass value="0.1"/>
      <inertia ixx="0.00001" ixy="0.0" ixz="0.0" iyy="0.00001" iyz="0.0" izz="0.00001"/>
    </inertial>
  </link>
  <joint name="left_front_steering_joint" type="revolute">
    <origin rpy="0.0 0.0 0.0" xyz="0.072 0.079 -0.0425"/>
    <parent link="base_link"/>
    <child link="left_front_knuckle"/>
    <axis xyz="0.0 0.0 1.0"/>
    <limit effort="10.0" lower="-0.6055" upper="0.6055" velocity="10.0"/>
  </joint>
  <link name="left_front_wheel">
    <inertial>
      <origin rpy="0.0 0.0 0.0" xyz="0.0 0.0 0.0"/>
      <mass value="0.1"/>
      <inertia ixx="0.0001" ixy="0.0" ixz="0.0" iyy="0.0001" iyz="0.0" izz="0.0001"/>
    </inertial>
    <visual>
      <origin rpy="1.5708 0.0 0.0" xyz="0.0 0.0 0.0"/>
      <geometry>
        <cylinder length="0.026" radius="0.034"/>
      </geometry>
      <material name="black"/>
    </visual>
    <collision>
      <origin rpy="1.5708 0.0 0.0" xyz="0.0 0.0 0.0"/>
      <geometry>
        <cylinder length="0.026" radius="0.034"/>
      </geometry>
    </collision>
  </link>
  <joint name="left_front_rolling_joint" type="continuous">
    <origin rpy="0.0 0.0 0.0" xyz="0.0 0.0 0.0"/>
    <parent link="left_front_knuckle"/>
    <child link="left_front_wheel"/>
    <axis xyz="0.0 1.0 0.0"/>
  </joint>
  <link name="right_front_knuckle">
    <inertial>
      <origin rpy="0.0 0.0 0.0" xyz="0.0 0.0 0.0"/>
      <mass value="0.1"/>
      <inertia ixx="0.00001" ixy="0.0" ixz="0.0" iyy="0.00001" iyz="0.0" izz="0.00001"/>
    </inertial>
  </link>
  <joint name="right_front_steering_joint" type="revolute">
    <origin rpy="0.0 0.0 0.0" xyz="0.072 -0.079 -0.0425"/>
    <parent link="base_link"/>
    <child link="right_front_knuckle"/>
    <axis xyz="0.0 0.0 1.0"/>
    <limit effort="10.0" lower="-0.6055" upper="0.6055" velocity="10.0"/>
  </joint>
  <link name="right_front_wheel">
    <inertial>
      <origin rpy="0.0 0.0 0.0" xyz="0.0 0.0 0.0"/>
      <mass value="0.1"/>
      <inertia ixx="0.0001" ixy="0.0" ixz="0.0" iyy="0.0001" iyz="0.0" izz="0.0001"/>
    </inertial>
    <visual>
      <origin rpy="1.5708 0.0 0.0" xyz="0.0 0.0 0.0"/>
      <geometry>
        <cylinder length="0.026" radius="0.034"/>
      </geometry>
      <material name="black"/>
    </visual>
    <collision>
      <origin rpy="1.5708 0.0 0.0" xyz="0.0 0.0 0.0"/>
      <geometry>
        <cylinder length="0.026" radius="0.034"/>
      </geometry>
    </collision>
  </link>
  <joint name="right_front_rolling_joint" type="continuous">
    <origin rpy="0.0 0.0 0.0" xyz="0.0 0.0 0.0"/>
    <parent link="right_front_knuckle"/>
    <child link="right_front_wheel"/>
    <axis xyz="0.0 1.0 0.0"/>
  </joint>
  <link name="left_rear_wheel">
    <inertial>
      <origin rpy="0.0 0.0 0.0" xyz="0.0 0.0 0.0"/>
      <mass value="0.1"/>
      <inertia ixx="0.0001" ixy="0.0" ixz="0.0" iyy="0.0001" iyz="0.0" izz="0.0001"/>
    </inertial>
    <visual>
      <origin rpy="1.5708 0.0 0.0" xyz="0.0 0.0 0.0"/>
      <geometry>
        <cylinder length="0.026" radius="0.034"/>
      </geometry>
      <material name="black"/>
    </visual>
    <collision>
      <origin rpy="1.5708 0.0 0.0" xyz="0.0 0.0 0.0"/>
      <geometry>
        <cylinder length="0.026" radius="0.034"/>
      </geometry>
    </collision>
  </link>
  <joint name="left_rear_rolling_joint" type="continuous">
    <origin rpy="0.0 0.0 0.0" xyz="-0.072 0.079 -0.0425"/>
    <parent link="base_link"/>
    <child link="left_rear_wheel"/>
    <axis xyz="0.0 1.0 0.0"/>
  </joint>
  <link name="right_rear_wheel">
    <inertial>
      <origin rpy="0.0 0.0 0.0" xyz="0.0 0.0 0.0"/>
      <mass value="0.1"/>
      <inertia ixx="0.0001" ixy="0.0" ixz="0.0" iyy="0.0001" iyz="0.0" izz="0.0001"/>
    </inertial>
    <visual>
      <origin rpy="1.5708 0.0 0.0" xyz="0.0 0.0 0.0"/>
      <geometry>
        <cylinder length="0.026" radius="0.034"/>
      </geometry>
      <material name="black"/>
    </visual>
    <collision>
      <origin rpy="1.5708 0.0 0.0" xyz="0.0 0.0 0.0"/>
      <geometry>
        <cylinder length="0.026" radius="0.034"/>
      </geometry>
    </collision>
  </link>
  <joint name="right_rear_rolling_joint" type="continuous">
    <origin rpy="0.0 0.0 0.0" xyz="-0.072 -0.079 -0.0425"/>
    <parent link="base_link"/>
    <child link="right_rear_wheel"/>
    <axis xyz="0.0 1.0 0.0"/>
  </joint>
  <link name="laser_link">
    <inertial>
      <origin rpy="0.0 0.0 0.0" xyz="0.0 0.0 0.0"/>
      <mass value="0.3"/>
      <inertia ixx="0.000154" ixy="0.0" ixz="0.0" iyy="0.000154" iyz="0.0" izz="0.000228"/>
    </inertial>
    <visual>
      <origin rpy="0.0 0.0 0.0" xyz="0.0 0.0 0.0"/>
      <geometry>
        <cylinder length="0.04" radius="0.039"/>
      </geometry>
      <material name="black"/>
    </visual>
    <collision>
      <origin rpy="0.0 0.0 0.0" xyz="0.0 0.0 0.0"/>
      <geometry>
        <cylinder length="0.04" radius="0.039"/>
      </geometry>
    </collision>
  </link>
  <joint name="laser_joint" type="fixed">
    <origin rpy="0.0 0.0 0.0" xyz="0.059 0.0 0.109"/>
    <parent link="base_link"/>
    <child link="laser_link"/>
    <axis xyz="0.0 0.0 0.0"/>
  </joint>
  <gazebo reference="laser_link">
    <sensor name="laserscan" type="ray">
      <plugin filename="libgazebo_ros_ray_sensor.so" name="laserscan">
        <ros>
          <namespace>/</namespace>
          <remapping>~/out:=scan</remapping>
        </ros>
        <output_type>sensor_msgs/LaserScan</output_type>
        <frame_name>laser_link</frame_name>
      </plugin>
      <always_on>true</always_on>
      <visualize>false</visualize>
      <update_rate>5</update_rate>
      <pose>0 0 0 0 0 0</pose>
      <ray>
        <scan>
          <horizontal>
            <samples>1500</samples>
            <resolution>1.000000</resolution>
            <min_angle>0.000000</min_angle>
            <max_angle>6.280000</max_angle>
          </horizontal>
        </scan>
        <range>
          <min>0.120000</min>
          <max>10.0</max>
          <resolution>0.015000</resolution>
        </range>
        <noise>
          <type>gaussian</type>
          <mean>0.0</mean>
          <stddev>0.01</stddev>
        </noise>
      </ray>
    </sensor>
  </gazebo>
  <link name="camera_body_link">
    <inertial>
      <origin rpy="0.0 0.0 0.0" xyz="0.0 0.0 0.0"/>
      <mass value="0.05"/>
      <inertia ixx="0.000057" ixy="0.0" ixz="0.0" iyy="0.000003" iyz="0.0" izz="0.000056"/>
    </inertial>
    <visual>
      <origin rpy="0.0 0.0 0.0" xyz="0.0 0.0 0.0"/>
      <geometry>
        <box size="0.017 0.115 0.022"/>
      </geometry>
      <material name="black"/>
    </visual>
    <collision>
      <origin rpy="0.0 0.0 0.0" xyz="0.0 0.0 0.0"/>
      <geometry>
        <box size="0.017 0.115 0.022"/>
      </geometry>
    </collision>
  </link>
  <link name="camera_pitch_link">
    <inertial>
      <origin rpy="0.0 0.0 0.0" xyz="0.0 0.0 0.0"/>
      <mass value="0.1"/>
      <inertia ixx="0.00001" ixy="0.0" ixz="0.0" iyy="0.00001" iyz="0.0" izz="0.00001"/>
    </inertial>
  </link>
  <joint name="camera_base_joint" type="revolute">
    <origin rpy="0.0 0.0 0.0" xyz="0.1325 0.0 0.0615"/>
    <parent link="base_link"/>
    <child link="camera_pitch_link"/>
    <axis xyz="0.0 1.0 0.0"/>
    <limit effort="1.0" lower="0.0" upper="0.7854" velocity="1.0"/>
  </joint>
  <joint name="camera_mount_joint" type="fixed">
    <origin rpy="0.0 0.0 0.0" xyz="-0.0085 0.0 0.011"/>
    <parent link="camera_pitch_link"/>
    <child link="camera_body_link"/>
    <axis xyz="0.0 0.0 0.0"/>
  </joint>
  <link name="camera_optical_link"/>
  <joint name="camera_optical_joint" type="fixed">
    <origin rpy="-1.5708 0 -1.5708" xyz="0 0 0"/>
    <parent link="camera_body_link"/>
    <child link="camera_optical_link"/>
  </joint>
  <gazebo reference="camera_body_link">
    <sensor name="gemini_pro_sensor" type="depth">
      <always_on>true</always_on>
      <update_rate>30.0</update_rate>
      <camera>
        <horizontal_fov>1.5708</horizontal_fov>
        <image>
          <width>800</width>
          <height>600</height>
          <format>R8G8B8</format>
        </image>
        <clip>
          <near>0.15</near>
          <far>10.0</far>
        </clip>
        <noise>
          <type>gaussian</type>
          <mean>0.0</mean>
          <stddev>0.007</stddev>
        </noise>
      </camera>
      <plugin filename="libgazebo_ros_camera.so" name="gemini_camera_controller">
        <ros>
          <namespace>/</namespace>
          <remapping>~/image_raw:=image_raw</remapping>
          <remapping>~/camera_info:=camera_info</remapping>
          <remapping>~/depth/image_raw:=depth/image_raw</remapping>
          <remapping>~/depth/camera_info:=depth/camera_info</remapping>
          <remapping>~/points:=points</remapping>
        </ros>
        <camera_name>gemini_pro</camera_name>
        <frame_name>camera_optical_link</frame_name>
        <min_depth>0.15</min_depth>
        <max_depth>10.0</max_depth>
      </plugin>
    </sensor>
  </gazebo>
  <ros2_control name="GazeboSystem" type="system">
    <hardware>
      <plugin>gazebo_ros2_control/GazeboSystem</plugin>
    </hardware>
    <joint name="left_rear_rolling_joint">
      <command_interface name="velocity">
        <param name="min">-10</param>
        <param name="max">10</param>
      </command_interface>
      <state_interface name="velocity"/>
      <state_interface name="position"/>
    </joint>
    <joint name="right_rear_rolling_joint">
      <command_interface name="velocity">
        <param name="min">-10</param>
        <param name="max">10</param>
      </command_interface>
      <state_interface name="velocity"/>
      <state_interface name="position"/>
    </joint>
    <joint name="left_front_steering_joint">
      <command_interface name="position">
        <param name="min">-0.6055</param>
        <param name="max">0.6055</param>
      </command_interface>
      <state_interface name="position"/>
    </joint>
    <joint name="right_front_steering_joint">
      <command_interface name="position">
        <param name="min">-0.6055</param>
        <param name="max">0.6055</param>
      </command_interface>
      <state_interface name="position"/>
    </joint>
    <joint name="left_front_rolling_joint">
      <state_interface name="velocity"/>
      <state_interface name="position"/>
    </joint>
    <joint name="right_front_rolling_joint">
      <state_interface name="velocity"/>
      <state_interface name="position"/>
    </joint>
    <joint name="camera_base_joint">
      <state_interface name="position"/>
      <state_interface name="velocity"/>
    </joint>
  </ros2_control>
  <gazebo>
    <plugin filename="libgazebo_ros2_control.so" name="gazebo_ros2_control">
      <parameters>/home/wuyang/wuyang_WS/install/wuyang_description/share/wuyang_description/config/ackermann_controller.yaml</parameters>
    </plugin>
  </gazebo>
</robot>
