<sdf version='1.7'>
  <world name='default'>
    <light name='sun' type='directional'>
      <cast_shadows>1</cast_shadows>
      <pose>0 0 10 0 -0 0</pose>
      <diffuse>0.8 0.8 0.8 1</diffuse>
      <specular>0.2 0.2 0.2 1</specular>
      <attenuation>
        <range>1000</range>
        <constant>0.9</constant>
        <linear>0.01</linear>
        <quadratic>0.001</quadratic>
      </attenuation>
      <direction>-0.5 0.1 -0.9</direction>
      <spot>
        <inner_angle>0</inner_angle>
        <outer_angle>0</outer_angle>
        <falloff>0</falloff>
      </spot>
    </light>
    <model name='ground_plane'>
      <static>1</static>
      <link name='link'>
        <collision name='collision'>
          <geometry>
            <plane>
              <normal>0 0 1</normal>
              <size>100 100</size>
            </plane>
          </geometry>
          <surface>
            <contact>
              <collide_bitmask>65535</collide_bitmask>
              <ode/>
            </contact>
            <friction>
              <ode>
                <mu>100</mu>
                <mu2>50</mu2>
              </ode>
              <torsional>
                <ode/>
              </torsional>
            </friction>
            <bounce/>
          </surface>
          <max_contacts>10</max_contacts>
        </collision>
        <visual name='visual'>
          <cast_shadows>0</cast_shadows>
          <geometry>
            <plane>
              <normal>0 0 1</normal>
              <size>100 100</size>
            </plane>
          </geometry>
          <material>
            <script>
              <uri>file://media/materials/scripts/gazebo.material</uri>
              <name>Gazebo/Grey</name>
            </script>
          </material>
        </visual>
        <self_collide>0</self_collide>
        <enable_wind>0</enable_wind>
        <kinematic>0</kinematic>
      </link>
    </model>
    <gravity>0 0 -9.8</gravity>
    <magnetic_field>6e-06 2.3e-05 -4.2e-05</magnetic_field>
    <atmosphere type='adiabatic'/>
    <physics type='ode'>
      <max_step_size>0.001</max_step_size>
      <real_time_factor>1</real_time_factor>
      <real_time_update_rate>1000</real_time_update_rate>
    </physics>
    <scene>
      <ambient>0.4 0.4 0.4 1</ambient>
      <background>0.7 0.7 0.7 1</background>
      <shadows>1</shadows>
    </scene>
    <audio>
      <device>default</device>
    </audio>
    <wind/>
    <spherical_coordinates>
      <surface_model>EARTH_WGS84</surface_model>
      <latitude_deg>0</latitude_deg>
      <longitude_deg>0</longitude_deg>
      <elevation>0</elevation>
      <heading_deg>0</heading_deg>
    </spherical_coordinates>
    <model name='wuyang_car'>
      <link name='base_footprint'>
        <inertial>
          <pose>0.005364 0 0.086409 0 -0 0</pose>
          <mass>3.3</mass>
          <inertia>
            <ixx>0.0101943</ixx>
            <ixy>0</ixy>
            <ixz>-0.00175391</ixz>
            <iyy>0.0256436</iyy>
            <iyz>0</iyz>
            <izz>0.0217774</izz>
          </inertia>
        </inertial>
        <collision name='base_footprint_fixed_joint_lump__base_link_collision'>
          <pose>0 0 0.0765 0 -0 0</pose>
          <geometry>
            <box>
              <size>0.265 0.11 0.123</size>
            </box>
          </geometry>
          <max_contacts>10</max_contacts>
          <surface>
            <contact>
              <ode/>
            </contact>
            <bounce/>
            <friction>
              <torsional>
                <ode/>
              </torsional>
              <ode/>
            </friction>
          </surface>
        </collision>
        <collision name='base_footprint_fixed_joint_lump__laser_link_collision_1'>
          <pose>0.059 0 0.1855 0 -0 0</pose>
          <geometry>
            <cylinder>
              <length>0.04</length>
              <radius>0.039</radius>
            </cylinder>
          </geometry>
          <surface>
            <contact>
              <ode/>
            </contact>
            <friction>
              <ode/>
              <torsional>
                <ode/>
              </torsional>
            </friction>
            <bounce/>
          </surface>
          <max_contacts>10</max_contacts>
        </collision>
        <visual name='base_footprint_fixed_joint_lump__RectangularPrism_visual'>
          <pose>0 0 0.0765 0 -0 0</pose>
          <geometry>
            <box>
              <size>0.265 0.11 0.123</size>
            </box>
          </geometry>
        </visual>
        <visual name='base_footprint_fixed_joint_lump__laser_link_visual_1'>
          <pose>0.059 0 0.1855 0 -0 0</pose>
          <geometry>
            <cylinder>
              <length>0.04</length>
              <radius>0.039</radius>
            </cylinder>
          </geometry>
        </visual>
        <sensor name='laserscan' type='ray'>
          <plugin name='laserscan' filename='libgazebo_ros_ray_sensor.so'>
            <ros>
              <namespace>/</namespace>
              <remapping>~/out:=scan</remapping>
            </ros>
            <output_type>sensor_msgs/LaserScan</output_type>
            <frame_name>laser_link</frame_name>
          </plugin>
          <always_on>1</always_on>
          <visualize>0</visualize>
          <update_rate>5</update_rate>
          <ray>
            <scan>
              <horizontal>
                <samples>1500</samples>
                <resolution>1</resolution>
                <min_angle>0</min_angle>
                <max_angle>6.28</max_angle>
              </horizontal>
              <vertical>
                <samples>1</samples>
                <min_angle>0</min_angle>
                <max_angle>0</max_angle>
              </vertical>
            </scan>
            <range>
              <min>0.12</min>
              <max>10</max>
              <resolution>0.015</resolution>
            </range>
            <noise>
              <type>gaussian</type>
              <mean>0</mean>
              <stddev>0.01</stddev>
            </noise>
          </ray>
          <pose>0.059 0 0.1855 0 -0 0</pose>
        </sensor>
        <self_collide>0</self_collide>
        <enable_wind>0</enable_wind>
        <kinematic>0</kinematic>
      </link>
      <joint name='camera_base_joint' type='revolute'>
        <pose relative_to='base_footprint'>0.1325 0 0.138 0 -0 0</pose>
        <parent>base_footprint</parent>
        <child>camera_pitch_link</child>
        <axis>
          <xyz>0 1 0</xyz>
          <limit>
            <lower>0</lower>
            <upper>0.7854</upper>
            <effort>1</effort>
            <velocity>1</velocity>
          </limit>
          <dynamics>
            <spring_reference>0</spring_reference>
            <spring_stiffness>0</spring_stiffness>
          </dynamics>
        </axis>
      </joint>
      <link name='camera_pitch_link'>
        <pose relative_to='camera_base_joint'>0 0 0 0 -0 0</pose>
        <inertial>
          <pose>-0.002833 0 0.003667 0 -0 0</pose>
          <mass>0.15</mass>
          <inertia>
            <ixx>7.10333e-05</ixx>
            <ixy>0</ixy>
            <ixz>3.11667e-06</ixz>
            <iyy>1.94417e-05</iyy>
            <iyz>0</iyz>
            <izz>6.84083e-05</izz>
          </inertia>
        </inertial>
        <collision name='camera_pitch_link_fixed_joint_lump__camera_body_link_collision'>
          <pose>-0.0085 0 0.011 0 -0 0</pose>
          <geometry>
            <box>
              <size>0.017 0.115 0.022</size>
            </box>
          </geometry>
          <surface>
            <contact>
              <ode/>
            </contact>
            <friction>
              <ode/>
              <torsional>
                <ode/>
              </torsional>
            </friction>
            <bounce/>
          </surface>
          <max_contacts>10</max_contacts>
        </collision>
        <visual name='camera_pitch_link_fixed_joint_lump__camera_body_link_visual'>
          <pose>-0.0085 0 0.011 0 -0 0</pose>
          <geometry>
            <box>
              <size>0.017 0.115 0.022</size>
            </box>
          </geometry>
        </visual>
        <sensor name='gemini_pro_sensor' type='depth'>
          <always_on>1</always_on>
          <update_rate>30</update_rate>
          <camera>
            <horizontal_fov>1.5708</horizontal_fov>
            <image>
              <width>800</width>
              <height>600</height>
              <format>R8G8B8</format>
            </image>
            <clip>
              <near>0.15</near>
              <far>10</far>
            </clip>
            <noise>
              <type>gaussian</type>
              <mean>0</mean>
              <stddev>0.007</stddev>
            </noise>
          </camera>
          <plugin name='gemini_camera_controller' filename='libgazebo_ros_camera.so'>
            <ros>
              <namespace>/</namespace>
              <remapping>~/image_raw:=image_raw</remapping>
              <remapping>~/camera_info:=camera_info</remapping>
              <remapping>~/depth/image_raw:=depth/image_raw</remapping>
              <remapping>~/depth/camera_info:=depth/camera_info</remapping>
              <remapping>~/points:=points</remapping>
            </ros>
            <camera_name>gemini_pro</camera_name>
            <frame_name>camera_optical_link</frame_name>
            <min_depth>0.15</min_depth>
            <max_depth>10.0</max_depth>
          </plugin>
          <pose>-0.0085 0 0.011 0 -0 0</pose>
        </sensor>
        <self_collide>0</self_collide>
        <enable_wind>0</enable_wind>
        <kinematic>0</kinematic>
      </link>
      <joint name='left_front_steering_joint' type='revolute'>
        <pose relative_to='base_footprint'>0.072 0.079 0.034 0 -0 0</pose>
        <parent>base_footprint</parent>
        <child>left_front_knuckle</child>
        <axis>
          <xyz>0 0 1</xyz>
          <limit>
            <lower>-0.6055</lower>
            <upper>0.6055</upper>
            <effort>10</effort>
            <velocity>10</velocity>
          </limit>
          <dynamics>
            <spring_reference>0</spring_reference>
            <spring_stiffness>0</spring_stiffness>
          </dynamics>
        </axis>
      </joint>
      <link name='left_front_knuckle'>
        <pose relative_to='left_front_steering_joint'>0 0 0 0 -0 0</pose>
        <inertial>
          <pose>0 0 0 0 -0 0</pose>
          <mass>0.1</mass>
          <inertia>
            <ixx>1e-05</ixx>
            <ixy>0</ixy>
            <ixz>0</ixz>
            <iyy>1e-05</iyy>
            <iyz>0</iyz>
            <izz>1e-05</izz>
          </inertia>
        </inertial>
        <self_collide>0</self_collide>
        <enable_wind>0</enable_wind>
        <kinematic>0</kinematic>
      </link>
      <joint name='left_front_rolling_joint' type='revolute'>
        <pose relative_to='left_front_knuckle'>0 0 0 0 -0 0</pose>
        <parent>left_front_knuckle</parent>
        <child>left_front_wheel</child>
        <axis>
          <xyz>0 1 0</xyz>
          <limit>
            <lower>-1e+16</lower>
            <upper>1e+16</upper>
          </limit>
          <dynamics>
            <spring_reference>0</spring_reference>
            <spring_stiffness>0</spring_stiffness>
          </dynamics>
        </axis>
      </joint>
      <link name='left_front_wheel'>
        <pose relative_to='left_front_rolling_joint'>0 0 0 0 -0 0</pose>
        <inertial>
          <pose>0 0 0 0 -0 0</pose>
          <mass>0.1</mass>
          <inertia>
            <ixx>0.0001</ixx>
            <ixy>0</ixy>
            <ixz>0</ixz>
            <iyy>0.0001</iyy>
            <iyz>0</iyz>
            <izz>0.0001</izz>
          </inertia>
        </inertial>
        <collision name='left_front_wheel_collision'>
          <pose>0 0 0 1.5708 -0 0</pose>
          <geometry>
            <cylinder>
              <length>0.026</length>
              <radius>0.034</radius>
            </cylinder>
          </geometry>
          <max_contacts>10</max_contacts>
          <surface>
            <contact>
              <ode/>
            </contact>
            <bounce/>
            <friction>
              <torsional>
                <ode/>
              </torsional>
              <ode/>
            </friction>
          </surface>
        </collision>
        <visual name='left_front_wheel_visual'>
          <pose>0 0 0 1.5708 -0 0</pose>
          <geometry>
            <cylinder>
              <length>0.026</length>
              <radius>0.034</radius>
            </cylinder>
          </geometry>
        </visual>
        <self_collide>0</self_collide>
        <enable_wind>0</enable_wind>
        <kinematic>0</kinematic>
      </link>
      <joint name='left_rear_rolling_joint' type='revolute'>
        <pose relative_to='base_footprint'>-0.072 0.079 0.034 0 -0 0</pose>
        <parent>base_footprint</parent>
        <child>left_rear_wheel</child>
        <axis>
          <xyz>0 1 0</xyz>
          <limit>
            <lower>-1e+16</lower>
            <upper>1e+16</upper>
          </limit>
          <dynamics>
            <spring_reference>0</spring_reference>
            <spring_stiffness>0</spring_stiffness>
          </dynamics>
        </axis>
      </joint>
      <link name='left_rear_wheel'>
        <pose relative_to='left_rear_rolling_joint'>0 0 0 0 -0 0</pose>
        <inertial>
          <pose>0 0 0 0 -0 0</pose>
          <mass>0.1</mass>
          <inertia>
            <ixx>0.0001</ixx>
            <ixy>0</ixy>
            <ixz>0</ixz>
            <iyy>0.0001</iyy>
            <iyz>0</iyz>
            <izz>0.0001</izz>
          </inertia>
        </inertial>
        <collision name='left_rear_wheel_collision'>
          <pose>0 0 0 1.5708 -0 0</pose>
          <geometry>
            <cylinder>
              <length>0.026</length>
              <radius>0.034</radius>
            </cylinder>
          </geometry>
          <max_contacts>10</max_contacts>
          <surface>
            <contact>
              <ode/>
            </contact>
            <bounce/>
            <friction>
              <torsional>
                <ode/>
              </torsional>
              <ode/>
            </friction>
          </surface>
        </collision>
        <visual name='left_rear_wheel_visual'>
          <pose>0 0 0 1.5708 -0 0</pose>
          <geometry>
            <cylinder>
              <length>0.026</length>
              <radius>0.034</radius>
            </cylinder>
          </geometry>
        </visual>
        <self_collide>0</self_collide>
        <enable_wind>0</enable_wind>
        <kinematic>0</kinematic>
      </link>
      <joint name='right_front_steering_joint' type='revolute'>
        <pose relative_to='base_footprint'>0.072 -0.079 0.034 0 -0 0</pose>
        <parent>base_footprint</parent>
        <child>right_front_knuckle</child>
        <axis>
          <xyz>0 0 1</xyz>
          <limit>
            <lower>-0.6055</lower>
            <upper>0.6055</upper>
            <effort>10</effort>
            <velocity>10</velocity>
          </limit>
          <dynamics>
            <spring_reference>0</spring_reference>
            <spring_stiffness>0</spring_stiffness>
          </dynamics>
        </axis>
      </joint>
      <link name='right_front_knuckle'>
        <pose relative_to='right_front_steering_joint'>0 0 0 0 -0 0</pose>
        <inertial>
          <pose>0 0 0 0 -0 0</pose>
          <mass>0.1</mass>
          <inertia>
            <ixx>1e-05</ixx>
            <ixy>0</ixy>
            <ixz>0</ixz>
            <iyy>1e-05</iyy>
            <iyz>0</iyz>
            <izz>1e-05</izz>
          </inertia>
        </inertial>
        <self_collide>0</self_collide>
        <enable_wind>0</enable_wind>
        <kinematic>0</kinematic>
      </link>
      <joint name='right_front_rolling_joint' type='revolute'>
        <pose relative_to='right_front_knuckle'>0 0 0 0 -0 0</pose>
        <parent>right_front_knuckle</parent>
        <child>right_front_wheel</child>
        <axis>
          <xyz>0 1 0</xyz>
          <limit>
            <lower>-1e+16</lower>
            <upper>1e+16</upper>
          </limit>
          <dynamics>
            <spring_reference>0</spring_reference>
            <spring_stiffness>0</spring_stiffness>
          </dynamics>
        </axis>
      </joint>
      <link name='right_front_wheel'>
        <pose relative_to='right_front_rolling_joint'>0 0 0 0 -0 0</pose>
        <inertial>
          <pose>0 0 0 0 -0 0</pose>
          <mass>0.1</mass>
          <inertia>
            <ixx>0.0001</ixx>
            <ixy>0</ixy>
            <ixz>0</ixz>
            <iyy>0.0001</iyy>
            <iyz>0</iyz>
            <izz>0.0001</izz>
          </inertia>
        </inertial>
        <collision name='right_front_wheel_collision'>
          <pose>0 0 0 1.5708 -0 0</pose>
          <geometry>
            <cylinder>
              <length>0.026</length>
              <radius>0.034</radius>
            </cylinder>
          </geometry>
          <max_contacts>10</max_contacts>
          <surface>
            <contact>
              <ode/>
            </contact>
            <bounce/>
            <friction>
              <torsional>
                <ode/>
              </torsional>
              <ode/>
            </friction>
          </surface>
        </collision>
        <visual name='right_front_wheel_visual'>
          <pose>0 0 0 1.5708 -0 0</pose>
          <geometry>
            <cylinder>
              <length>0.026</length>
              <radius>0.034</radius>
            </cylinder>
          </geometry>
        </visual>
        <self_collide>0</self_collide>
        <enable_wind>0</enable_wind>
        <kinematic>0</kinematic>
      </link>
      <joint name='right_rear_rolling_joint' type='revolute'>
        <pose relative_to='base_footprint'>-0.072 -0.079 0.034 0 -0 0</pose>
        <parent>base_footprint</parent>
        <child>right_rear_wheel</child>
        <axis>
          <xyz>0 1 0</xyz>
          <limit>
            <lower>-1e+16</lower>
            <upper>1e+16</upper>
          </limit>
          <dynamics>
            <spring_reference>0</spring_reference>
            <spring_stiffness>0</spring_stiffness>
          </dynamics>
        </axis>
      </joint>
      <link name='right_rear_wheel'>
        <pose relative_to='right_rear_rolling_joint'>0 0 0 0 -0 0</pose>
        <inertial>
          <pose>0 0 0 0 -0 0</pose>
          <mass>0.1</mass>
          <inertia>
            <ixx>0.0001</ixx>
            <ixy>0</ixy>
            <ixz>0</ixz>
            <iyy>0.0001</iyy>
            <iyz>0</iyz>
            <izz>0.0001</izz>
          </inertia>
        </inertial>
        <collision name='right_rear_wheel_collision'>
          <pose>0 0 0 1.5708 -0 0</pose>
          <geometry>
            <cylinder>
              <length>0.026</length>
              <radius>0.034</radius>
            </cylinder>
          </geometry>
          <max_contacts>10</max_contacts>
          <surface>
            <contact>
              <ode/>
            </contact>
            <bounce/>
            <friction>
              <torsional>
                <ode/>
              </torsional>
              <ode/>
            </friction>
          </surface>
        </collision>
        <visual name='right_rear_wheel_visual'>
          <pose>0 0 0 1.5708 -0 0</pose>
          <geometry>
            <cylinder>
              <length>0.026</length>
              <radius>0.034</radius>
            </cylinder>
          </geometry>
        </visual>
        <self_collide>0</self_collide>
        <enable_wind>0</enable_wind>
        <kinematic>0</kinematic>
      </link>
      <static>0</static>
      <plugin name='gazebo_ros2_control' filename='libgazebo_ros2_control.so'>
        <parameters>/home/hhz/wuyang_ws/install/wuyang_description/share/wuyang_description/config/ackermann_controller.yaml</parameters>
      </plugin>
      <pose>0 0 0.05 0 -0 0</pose>
    </model>
    <state world_name='default'>
      <sim_time>1110 134000000</sim_time>
      <real_time>98 106673135</real_time>
      <wall_time>1783784149 421016300</wall_time>
      <iterations>95810</iterations>
      <model name='ground_plane'>
        <pose>0 0 0 0 -0 0</pose>
        <scale>1 1 1</scale>
        <link name='link'>
          <pose>0 0 0 0 -0 0</pose>
          <velocity>0 0 0 0 -0 0</velocity>
          <acceleration>0 0 0 0 -0 0</acceleration>
          <wrench>0 0 0 0 -0 0</wrench>
        </link>
      </model>
      <model name='sandbox_map'>
        <pose>0.224851 0.073986 0 0 -0 0</pose>
        <scale>1 1 1</scale>
        <link name='link'>
          <pose>0.224851 0.073986 0 0 -0 0</pose>
          <velocity>0 0 0 0 -0 0</velocity>
          <acceleration>0 0 0 0 -0 0</acceleration>
          <wrench>0 0 0 0 -0 0</wrench>
        </link>
      </model>
      <model name='wuyang_car'>
        <pose>0.069807 -0.004162 0.000493 -7.5e-05 1.2e-05 0.062083</pose>
        <scale>1 1 1</scale>
        <link name='base_footprint'>
          <pose>0.069807 -0.004162 0.000493 -7.5e-05 1.2e-05 0.062083</pose>
          <velocity>0.002386 -0.005763 -0.005696 -0.080339 -0.029616 0.000428</velocity>
          <acceleration>-0.381525 1.92022 -4.45441 -2.67818 -0.072609 -2.5164</acceleration>
          <wrench>-1.25903 6.33671 -14.6995 0 -0 0</wrench>
        </link>
        <link name='camera_pitch_link'>
          <pose>0.202053 0.004069 0.138491 -7.5e-05 -6.4e-05 0.062083</pose>
          <velocity>-0.001705 0.005392 -0.002442 -0.081607 -0.010481 0.000404</velocity>
          <acceleration>-3.01944 7.24398 0.668643 -2.97892 0.278946 -1.91329</acceleration>
          <wrench>-0.452915 1.0866 0.100296 0 -0 0</wrench>
        </link>
        <link name='left_front_knuckle'>
          <pose>0.136767 0.079155 0.034488 -3.7e-05 1.2e-05 0.062122</pose>
          <velocity>0.001358 -0.002853 -0.01088 -0.088841 -0.030116 -0.003612</velocity>
          <acceleration>1.72736 -2.18758 -9.20628 2.54287 0.230107 -2.83026</acceleration>
          <wrench>0.172736 -0.218758 -0.920628 0 -0 0</wrench>
        </link>
        <link name='left_front_wheel'>
          <pose>0.136767 0.079153 0.034489 -3.14149 0.556381 -3.07942</pose>
          <velocity>0.001348 -0.002447 -0.011202 -0.077194 -0.016984 -0.003889</velocity>
          <acceleration>1.72434 -1.21087 -10.8894 -1.10882 -0.821212 -0.026852</acceleration>
          <wrench>0.172434 -0.121088 -1.08894 0 -0 0</wrench>
        </link>
        <link name='left_rear_wheel'>
          <pose>-0.006955 0.070221 0.034487 -9.4e-05 -0.028685 0.062086</pose>
          <velocity>0.001363 -0.002998 -0.013691 -0.078023 0.012015 0.000312</velocity>
          <acceleration>1.76741 -2.89615 -14.4409 -2.34724 1.05976 -2.04689</acceleration>
          <wrench>0.176741 -0.289614 -1.44409 0 -0 0</wrench>
        </link>
        <link name='right_front_knuckle'>
          <pose>0.14657 -0.078539 0.034499 3e-05 1.3e-05 0.062098</pose>
          <velocity>0.001347 -0.002379 0.002973 0.046515 -0.021942 0.000531</velocity>
          <acceleration>2.33555 -1.67528 5.76282 2.8101 -1.48103 -1.82862</acceleration>
          <wrench>0.233556 -0.167528 0.576282 0 -0 0</wrench>
        </link>
        <link name='right_front_wheel'>
          <pose>0.14657 -0.078537 0.0345 3.14153 -0.403347 -3.07947</pose>
          <velocity>0.001269 -0.001306 0.003243 0.03838 0.037346 0.000426</velocity>
          <acceleration>2.22694 -0.266902 6.50001 -2.05659 -0.211428 -2.86222</acceleration>
          <wrench>0.222693 -0.02669 0.650001 0 -0 0</wrench>
        </link>
        <link name='right_rear_wheel'>
          <pose>0.002847 -0.087474 0.034499 -6.8e-05 0.025601 0.06208</pose>
          <velocity>0.001432 -0.003113 -0.000988 -0.084542 0.01161 0.000583</velocity>
          <acceleration>2.45603 -2.97294 -0.621787 -2.58348 0.654584 -1.77675</acceleration>
          <wrench>0.245603 -0.297294 -0.062179 0 -0 0</wrench>
        </link>
      </model>
      <light name='sun'>
        <pose>0 0 10 0 -0 0</pose>
      </light>
    </state>
    <gui fullscreen='0'>
      <camera name='user_camera'>
        <pose>-0.368322 -0.152627 7.03423 -1e-05 1.5698 -0.683842</pose>
        <view_controller>orbit</view_controller>
        <projection_type>perspective</projection_type>
      </camera>
    </gui>
    <model name='sandbox_map'>
      <static>1</static>
      <link name='link'>
        <collision name='collision'>
          <geometry>
            <box>
              <size>3.2 3.5 0.001</size>
            </box>
          </geometry>
          <surface>
            <friction>
              <ode>
                <mu>1</mu>
                <mu2>1</mu2>
              </ode>
              <torsional>
                <ode/>
              </torsional>
            </friction>
            <contact>
              <ode/>
            </contact>
            <bounce/>
          </surface>
          <max_contacts>10</max_contacts>
        </collision>
        <visual name='visual'>
          <cast_shadows>0</cast_shadows>
          <geometry>
            <box>
              <size>3.2 3.5 0.001</size>
            </box>
          </geometry>
          <material>
            <script>
              <uri>model://sandbox_map/materials/scripts</uri>
              <uri>model://sandbox_map/materials/textures</uri>
              <name>SandBoxMap/Diffuse</name>
            </script>
          </material>
        </visual>
        <self_collide>0</self_collide>
        <enable_wind>0</enable_wind>
        <kinematic>0</kinematic>
      </link>
      <pose>0.236314 0.052298 0 0 -0 0</pose>
    </model>
  </world>
</sdf>
