<sdf version='1.7'>
  <world name='default'>
    <light name='sun' type='directional'>
      <cast_shadows>1</cast_shadows>
      <pose>0 0 10 0 -0 0</pose>
      <diffuse>0.8 0.8 0.8 1</diffuse>
      <specular>0.2 0.2 0.2 1</specular>
      <attenuation>
        <range>1000</range>
        <constant>0.9</constant>
        <linear>0.01</linear>
        <quadratic>0.001</quadratic>
      </attenuation>
      <direction>-0.5 0.1 -0.9</direction>
      <spot>
        <inner_angle>0</inner_angle>
        <outer_angle>0</outer_angle>
        <falloff>0</falloff>
      </spot>
    </light>
    <model name='ground_plane'>
      <static>1</static>
      <link name='link'>
        <collision name='collision'>
          <geometry>
            <plane>
              <normal>0 0 1</normal>
              <size>100 100</size>
            </plane>
          </geometry>
          <surface>
            <contact>
              <collide_bitmask>65535</collide_bitmask>
              <ode/>
            </contact>
            <friction>
              <ode>
                <mu>100</mu>
                <mu2>50</mu2>
              </ode>
              <torsional>
                <ode/>
              </torsional>
            </friction>
            <bounce/>
          </surface>
          <max_contacts>10</max_contacts>
        </collision>
        <visual name='visual'>
          <cast_shadows>0</cast_shadows>
          <geometry>
            <plane>
              <normal>0 0 1</normal>
              <size>100 100</size>
            </plane>
          </geometry>
          <material>
            <script>
              <uri>file://media/materials/scripts/gazebo.material</uri>
              <name>Gazebo/Grey</name>
            </script>
          </material>
        </visual>
        <self_collide>0</self_collide>
        <enable_wind>0</enable_wind>
        <kinematic>0</kinematic>
      </link>
    </model>
    <gravity>0 0 -9.8</gravity>
    <magnetic_field>6e-06 2.3e-05 -4.2e-05</magnetic_field>
    <atmosphere type='adiabatic'/>
    <physics type='ode'>
      <max_step_size>0.001</max_step_size>
      <real_time_factor>1</real_time_factor>
      <real_time_update_rate>1000</real_time_update_rate>
    </physics>
    <scene>
      <ambient>0.4 0.4 0.4 1</ambient>
      <background>0.7 0.7 0.7 1</background>
      <shadows>1</shadows>
    </scene>
    <audio>
      <device>default</device>
    </audio>
    <wind/>
    <spherical_coordinates>
      <surface_model>EARTH_WGS84</surface_model>
      <latitude_deg>0</latitude_deg>
      <longitude_deg>0</longitude_deg>
      <elevation>0</elevation>
      <heading_deg>0</heading_deg>
    </spherical_coordinates>
    <model name='wuyang_car'>
      <link name='base_footprint'>
        <inertial>
          <pose>0.005364 0 0.086409 0 -0 0</pose>
          <mass>3.3</mass>
          <inertia>
            <ixx>0.0101943</ixx>
            <ixy>0</ixy>
            <ixz>-0.00175391</ixz>
            <iyy>0.0256436</iyy>
            <iyz>0</iyz>
            <izz>0.0217774</izz>
          </inertia>
        </inertial>
        <collision name='base_footprint_fixed_joint_lump__base_link_collision'>
          <pose>0 0 0.0765 0 -0 0</pose>
          <geometry>
            <box>
              <size>0.265 0.11 0.123</size>
            </box>
          </geometry>
          <max_contacts>10</max_contacts>
          <surface>
            <contact>
              <ode/>
            </contact>
            <bounce/>
            <friction>
              <torsional>
                <ode/>
              </torsional>
              <ode/>
            </friction>
          </surface>
        </collision>
        <collision name='base_footprint_fixed_joint_lump__laser_link_collision_1'>
          <pose>0.059 0 0.1855 0 -0 0</pose>
          <geometry>
            <cylinder>
              <length>0.04</length>
              <radius>0.039</radius>
            </cylinder>
          </geometry>
          <surface>
            <contact>
              <ode/>
            </contact>
            <friction>
              <ode/>
              <torsional>
                <ode/>
              </torsional>
            </friction>
            <bounce/>
          </surface>
          <max_contacts>10</max_contacts>
        </collision>
        <visual name='base_footprint_fixed_joint_lump__RectangularPrism_visual'>
          <pose>0 0 0.0765 0 -0 0</pose>
          <geometry>
            <box>
              <size>0.265 0.11 0.123</size>
            </box>
          </geometry>
        </visual>
        <visual name='base_footprint_fixed_joint_lump__laser_link_visual_1'>
          <pose>0.059 0 0.1855 0 -0 0</pose>
          <geometry>
            <cylinder>
              <length>0.04</length>
              <radius>0.039</radius>
            </cylinder>
          </geometry>
        </visual>
        <sensor name='laserscan' type='ray'>
          <plugin name='laserscan' filename='libgazebo_ros_ray_sensor.so'>
            <ros>
              <namespace>/</namespace>
              <remapping>~/out:=scan</remapping>
            </ros>
            <output_type>sensor_msgs/LaserScan</output_type>
            <frame_name>laser_link</frame_name>
          </plugin>
          <always_on>1</always_on>
          <visualize>0</visualize>
          <update_rate>5</update_rate>
          <ray>
            <scan>
              <horizontal>
                <samples>1500</samples>
                <resolution>1</resolution>
                <min_angle>0</min_angle>
                <max_angle>6.28</max_angle>
              </horizontal>
              <vertical>
                <samples>1</samples>
                <min_angle>0</min_angle>
                <max_angle>0</max_angle>
              </vertical>
            </scan>
            <range>
              <min>0.12</min>
              <max>10</max>
              <resolution>0.015</resolution>
            </range>
            <noise>
              <type>gaussian</type>
              <mean>0</mean>
              <stddev>0.01</stddev>
            </noise>
          </ray>
          <pose>0.059 0 0.1855 0 -0 0</pose>
        </sensor>
        <self_collide>0</self_collide>
        <enable_wind>0</enable_wind>
        <kinematic>0</kinematic>
      </link>
      <joint name='camera_base_joint' type='revolute'>
        <pose relative_to='base_footprint'>0.1325 0 0.138 0 -0 0</pose>
        <parent>base_footprint</parent>
        <child>camera_pitch_link</child>
        <axis>
          <xyz>0 1 0</xyz>
          <limit>
            <lower>0</lower>
            <upper>0.7854</upper>
            <effort>1</effort>
            <velocity>1</velocity>
          </limit>
          <dynamics>
            <spring_reference>0</spring_reference>
            <spring_stiffness>0</spring_stiffness>
          </dynamics>
        </axis>
      </joint>
      <link name='camera_pitch_link'>
        <pose relative_to='camera_base_joint'>0 0 0 0 -0 0</pose>
        <inertial>
          <pose>-0.002833 0 0.003667 0 -0 0</pose>
          <mass>0.15</mass>
          <inertia>
            <ixx>7.10333e-05</ixx>
            <ixy>0</ixy>
            <ixz>3.11667e-06</ixz>
            <iyy>1.94417e-05</iyy>
            <iyz>0</iyz>
            <izz>6.84083e-05</izz>
          </inertia>
        </inertial>
        <collision name='camera_pitch_link_fixed_joint_lump__camera_body_link_collision'>
          <pose>-0.0085 0 0.011 0 -0 0</pose>
          <geometry>
            <box>
              <size>0.017 0.115 0.022</size>
            </box>
          </geometry>
          <surface>
            <contact>
              <ode/>
            </contact>
            <friction>
              <ode/>
              <torsional>
                <ode/>
              </torsional>
            </friction>
            <bounce/>
          </surface>
          <max_contacts>10</max_contacts>
        </collision>
        <visual name='camera_pitch_link_fixed_joint_lump__camera_body_link_visual'>
          <pose>-0.0085 0 0.011 0 -0 0</pose>
          <geometry>
            <box>
              <size>0.017 0.115 0.022</size>
            </box>
          </geometry>
        </visual>
        <sensor name='gemini_pro_sensor' type='depth'>
          <always_on>1</always_on>
          <update_rate>30</update_rate>
          <camera>
            <horizontal_fov>1.5708</horizontal_fov>
            <image>
              <width>800</width>
              <height>600</height>
              <format>R8G8B8</format>
            </image>
            <clip>
              <near>0.15</near>
              <far>10</far>
            </clip>
            <noise>
              <type>gaussian</type>
              <mean>0</mean>
              <stddev>0.007</stddev>
            </noise>
          </camera>
          <plugin name='gemini_camera_controller' filename='libgazebo_ros_camera.so'>
            <ros>
              <namespace>/</namespace>
              <remapping>~/image_raw:=image_raw</remapping>
              <remapping>~/camera_info:=camera_info</remapping>
              <remapping>~/depth/image_raw:=depth/image_raw</remapping>
              <remapping>~/depth/camera_info:=depth/camera_info</remapping>
              <remapping>~/points:=points</remapping>
            </ros>
            <camera_name>gemini_pro</camera_name>
            <frame_name>camera_optical_link</frame_name>
            <min_depth>0.15</min_depth>
            <max_depth>10.0</max_depth>
          </plugin>
          <pose>-0.0085 0 0.011 0 -0 0</pose>
        </sensor>
        <self_collide>0</self_collide>
        <enable_wind>0</enable_wind>
        <kinematic>0</kinematic>
      </link>
      <joint name='left_front_steering_joint' type='revolute'>
        <pose relative_to='base_footprint'>0.072 0.079 0.034 0 -0 0</pose>
        <parent>base_footprint</parent>
        <child>left_front_knuckle</child>
        <axis>
          <xyz>0 0 1</xyz>
          <limit>
            <lower>-0.6055</lower>
            <upper>0.6055</upper>
            <effort>10</effort>
            <velocity>10</velocity>
          </limit>
          <dynamics>
            <spring_reference>0</spring_reference>
            <spring_stiffness>0</spring_stiffness>
          </dynamics>
        </axis>
      </joint>
      <link name='left_front_knuckle'>
        <pose relative_to='left_front_steering_joint'>0 0 0 0 -0 0</pose>
        <inertial>
          <pose>0 0 0 0 -0 0</pose>
          <mass>0.1</mass>
          <inertia>
            <ixx>1e-05</ixx>
            <ixy>0</ixy>
            <ixz>0</ixz>
            <iyy>1e-05</iyy>
            <iyz>0</iyz>
            <izz>1e-05</izz>
          </inertia>
        </inertial>
        <self_collide>0</self_collide>
        <enable_wind>0</enable_wind>
        <kinematic>0</kinematic>
      </link>
      <joint name='left_front_rolling_joint' type='revolute'>
        <pose relative_to='left_front_knuckle'>0 0 0 0 -0 0</pose>
        <parent>left_front_knuckle</parent>
        <child>left_front_wheel</child>
        <axis>
          <xyz>0 1 0</xyz>
          <limit>
            <lower>-1e+16</lower>
            <upper>1e+16</upper>
          </limit>
          <dynamics>
            <spring_reference>0</spring_reference>
            <spring_stiffness>0</spring_stiffness>
          </dynamics>
        </axis>
      </joint>
      <link name='left_front_wheel'>
        <pose relative_to='left_front_rolling_joint'>0 0 0 0 -0 0</pose>
        <inertial>
          <pose>0 0 0 0 -0 0</pose>
          <mass>0.1</mass>
          <inertia>
            <ixx>0.0001</ixx>
            <ixy>0</ixy>
            <ixz>0</ixz>
            <iyy>0.0001</iyy>
            <iyz>0</iyz>
            <izz>0.0001</izz>
          </inertia>
        </inertial>
        <collision name='left_front_wheel_collision'>
          <pose>0 0 0 1.5708 -0 0</pose>
          <geometry>
            <cylinder>
              <length>0.026</length>
              <radius>0.034</radius>
            </cylinder>
          </geometry>
          <max_contacts>10</max_contacts>
          <surface>
            <contact>
              <ode/>
            </contact>
            <bounce/>
            <friction>
              <torsional>
                <ode/>
              </torsional>
              <ode/>
            </friction>
          </surface>
        </collision>
        <visual name='left_front_wheel_visual'>
          <pose>0 0 0 1.5708 -0 0</pose>
          <geometry>
            <cylinder>
              <length>0.026</length>
              <radius>0.034</radius>
            </cylinder>
          </geometry>
        </visual>
        <self_collide>0</self_collide>
        <enable_wind>0</enable_wind>
        <kinematic>0</kinematic>
      </link>
      <joint name='left_rear_rolling_joint' type='revolute'>
        <pose relative_to='base_footprint'>-0.072 0.079 0.034 0 -0 0</pose>
        <parent>base_footprint</parent>
        <child>left_rear_wheel</child>
        <axis>
          <xyz>0 1 0</xyz>
          <limit>
            <lower>-1e+16</lower>
            <upper>1e+16</upper>
          </limit>
          <dynamics>
            <spring_reference>0</spring_reference>
            <spring_stiffness>0</spring_stiffness>
          </dynamics>
        </axis>
      </joint>
      <link name='left_rear_wheel'>
        <pose relative_to='left_rear_rolling_joint'>0 0 0 0 -0 0</pose>
        <inertial>
          <pose>0 0 0 0 -0 0</pose>
          <mass>0.1</mass>
          <inertia>
            <ixx>0.0001</ixx>
            <ixy>0</ixy>
            <ixz>0</ixz>
            <iyy>0.0001</iyy>
            <iyz>0</iyz>
            <izz>0.0001</izz>
          </inertia>
        </inertial>
        <collision name='left_rear_wheel_collision'>
          <pose>0 0 0 1.5708 -0 0</pose>
          <geometry>
            <cylinder>
              <length>0.026</length>
              <radius>0.034</radius>
            </cylinder>
          </geometry>
          <max_contacts>10</max_contacts>
          <surface>
            <contact>
              <ode/>
            </contact>
            <bounce/>
            <friction>
              <torsional>
                <ode/>
              </torsional>
              <ode/>
            </friction>
          </surface>
        </collision>
        <visual name='left_rear_wheel_visual'>
          <pose>0 0 0 1.5708 -0 0</pose>
          <geometry>
            <cylinder>
              <length>0.026</length>
              <radius>0.034</radius>
            </cylinder>
          </geometry>
        </visual>
        <self_collide>0</self_collide>
        <enable_wind>0</enable_wind>
        <kinematic>0</kinematic>
      </link>
      <joint name='right_front_steering_joint' type='revolute'>
        <pose relative_to='base_footprint'>0.072 -0.079 0.034 0 -0 0</pose>
        <parent>base_footprint</parent>
        <child>right_front_knuckle</child>
        <axis>
          <xyz>0 0 1</xyz>
          <limit>
            <lower>-0.6055</lower>
            <upper>0.6055</upper>
            <effort>10</effort>
            <velocity>10</velocity>
          </limit>
          <dynamics>
            <spring_reference>0</spring_reference>
            <spring_stiffness>0</spring_stiffness>
          </dynamics>
        </axis>
      </joint>
      <link name='right_front_knuckle'>
        <pose relative_to='right_front_steering_joint'>0 0 0 0 -0 0</pose>
        <inertial>
          <pose>0 0 0 0 -0 0</pose>
          <mass>0.1</mass>
          <inertia>
            <ixx>1e-05</ixx>
            <ixy>0</ixy>
            <ixz>0</ixz>
            <iyy>1e-05</iyy>
            <iyz>0</iyz>
            <izz>1e-05</izz>
          </inertia>
        </inertial>
        <self_collide>0</self_collide>
        <enable_wind>0</enable_wind>
        <kinematic>0</kinematic>
      </link>
      <joint name='right_front_rolling_joint' type='revolute'>
        <pose relative_to='right_front_knuckle'>0 0 0 0 -0 0</pose>
        <parent>right_front_knuckle</parent>
        <child>right_front_wheel</child>
        <axis>
          <xyz>0 1 0</xyz>
          <limit>
            <lower>-1e+16</lower>
            <upper>1e+16</upper>
          </limit>
          <dynamics>
            <spring_reference>0</spring_reference>
            <spring_stiffness>0</spring_stiffness>
          </dynamics>
        </axis>
      </joint>
      <link name='right_front_wheel'>
        <pose relative_to='right_front_rolling_joint'>0 0 0 0 -0 0</pose>
        <inertial>
          <pose>0 0 0 0 -0 0</pose>
          <mass>0.1</mass>
          <inertia>
            <ixx>0.0001</ixx>
            <ixy>0</ixy>
            <ixz>0</ixz>
            <iyy>0.0001</iyy>
            <iyz>0</iyz>
            <izz>0.0001</izz>
          </inertia>
        </inertial>
        <collision name='right_front_wheel_collision'>
          <pose>0 0 0 1.5708 -0 0</pose>
          <geometry>
            <cylinder>
              <length>0.026</length>
              <radius>0.034</radius>
            </cylinder>
          </geometry>
          <max_contacts>10</max_contacts>
          <surface>
            <contact>
              <ode/>
            </contact>
            <bounce/>
            <friction>
              <torsional>
                <ode/>
              </torsional>
              <ode/>
            </friction>
          </surface>
        </collision>
        <visual name='right_front_wheel_visual'>
          <pose>0 0 0 1.5708 -0 0</pose>
          <geometry>
            <cylinder>
              <length>0.026</length>
              <radius>0.034</radius>
            </cylinder>
          </geometry>
        </visual>
        <self_collide>0</self_collide>
        <enable_wind>0</enable_wind>
        <kinematic>0</kinematic>
      </link>
      <joint name='right_rear_rolling_joint' type='revolute'>
        <pose relative_to='base_footprint'>-0.072 -0.079 0.034 0 -0 0</pose>
        <parent>base_footprint</parent>
        <child>right_rear_wheel</child>
        <axis>
          <xyz>0 1 0</xyz>
          <limit>
            <lower>-1e+16</lower>
            <upper>1e+16</upper>
          </limit>
          <dynamics>
            <spring_reference>0</spring_reference>
            <spring_stiffness>0</spring_stiffness>
          </dynamics>
        </axis>
      </joint>
      <link name='right_rear_wheel'>
        <pose relative_to='right_rear_rolling_joint'>0 0 0 0 -0 0</pose>
        <inertial>
          <pose>0 0 0 0 -0 0</pose>
          <mass>0.1</mass>
          <inertia>
            <ixx>0.0001</ixx>
            <ixy>0</ixy>
            <ixz>0</ixz>
            <iyy>0.0001</iyy>
            <iyz>0</iyz>
            <izz>0.0001</izz>
          </inertia>
        </inertial>
        <collision name='right_rear_wheel_collision'>
          <pose>0 0 0 1.5708 -0 0</pose>
          <geometry>
            <cylinder>
              <length>0.026</length>
              <radius>0.034</radius>
            </cylinder>
          </geometry>
          <max_contacts>10</max_contacts>
          <surface>
            <contact>
              <ode/>
            </contact>
            <bounce/>
            <friction>
              <torsional>
                <ode/>
              </torsional>
              <ode/>
            </friction>
          </surface>
        </collision>
        <visual name='right_rear_wheel_visual'>
          <pose>0 0 0 1.5708 -0 0</pose>
          <geometry>
            <cylinder>
              <length>0.026</length>
              <radius>0.034</radius>
            </cylinder>
          </geometry>
        </visual>
        <self_collide>0</self_collide>
        <enable_wind>0</enable_wind>
        <kinematic>0</kinematic>
      </link>
      <static>0</static>
      <plugin name='gazebo_ros2_control' filename='libgazebo_ros2_control.so'>
        <parameters>/home/hhz/wuyang_ws/install/wuyang_description/share/wuyang_description/config/ackermann_controller.yaml</parameters>
      </plugin>
      <pose>0 0 0.05 0 -0 0</pose>
    </model>
    <model name='unit_sphere'>
      <pose>1.94972 -0.273015 0.5 0 -0 0</pose>
      <link name='link'>
        <inertial>
          <mass>1</mass>
          <inertia>
            <ixx>0.1</ixx>
            <ixy>0</ixy>
            <ixz>0</ixz>
            <iyy>0.1</iyy>
            <iyz>0</iyz>
            <izz>0.1</izz>
          </inertia>
          <pose>0 0 0 0 -0 0</pose>
        </inertial>
        <collision name='collision'>
          <geometry>
            <sphere>
              <radius>0.5</radius>
            </sphere>
          </geometry>
          <max_contacts>10</max_contacts>
          <surface>
            <contact>
              <ode/>
            </contact>
            <bounce/>
            <friction>
              <torsional>
                <ode/>
              </torsional>
              <ode/>
            </friction>
          </surface>
        </collision>
        <visual name='visual'>
          <geometry>
            <sphere>
              <radius>0.5</radius>
            </sphere>
          </geometry>
          <material>
            <script>
              <name>Gazebo/Grey</name>
              <uri>file://media/materials/scripts/gazebo.material</uri>
            </script>
          </material>
        </visual>
        <self_collide>0</self_collide>
        <enable_wind>0</enable_wind>
        <kinematic>0</kinematic>
      </link>
    </model>
    <state world_name='default'>
      <sim_time>127 488000000</sim_time>
      <real_time>130 496023163</real_time>
      <wall_time>1779098761 275348253</wall_time>
      <iterations>127488</iterations>
      <model name='ground_plane'>
        <pose>0 0 0 0 -0 0</pose>
        <scale>1 1 1</scale>
        <link name='link'>
          <pose>0 0 0 0 -0 0</pose>
          <velocity>0 0 0 0 -0 0</velocity>
          <acceleration>0 0 0 0 -0 0</acceleration>
          <wrench>0 0 0 0 -0 0</wrench>
        </link>
      </model>
      <model name='unit_sphere'>
        <pose>1.94972 -0.273015 0.5 0 -0 0</pose>
        <scale>1 1 1</scale>
        <link name='link'>
          <pose>1.94972 -0.273015 0.5 0 -0 0</pose>
          <velocity>0 0 0 0 -0 0</velocity>
          <acceleration>0 0 0 0 -0 0</acceleration>
          <wrench>0 0 0 0 -0 0</wrench>
        </link>
      </model>
      <model name='wuyang_car'>
        <pose>0.008984 -0.00779 -1e-06 -0 3.2e-05 -0.000632</pose>
        <scale>1 1 1</scale>
        <link name='base_footprint'>
          <pose>0.008984 -0.00779 -1e-06 -0 3.2e-05 -0.000632</pose>
          <velocity>-5e-06 -0.00051 -7e-06 0.000499 7.2e-05 -0.004896</velocity>
          <acceleration>-0.000138 -1.16016 -0.01429 0.998526 0.145246 2.77577</acceleration>
          <wrench>-0.000455 -3.82854 -0.047156 0 -0 0</wrench>
        </link>
        <link name='camera_pitch_link'>
          <pose>0.141488 -0.007874 0.137994 0 2.4e-05 -0.000632</pose>
          <velocity>5e-06 -0.00123 -1.6e-05 0.000518 0.002099 -0.004893</velocity>
          <acceleration>0.005292 -2.43683 -0.033959 1.03354 -0.361523 2.78111</acceleration>
          <wrench>0.000794 -0.365525 -0.005094 0 -0 0</wrench>
        </link>
        <link name='left_front_knuckle'>
          <pose>0.081035 0.071164 0.033998 2e-05 3.2e-05 -0.000633</pose>
          <velocity>0.000378 -0.000942 1.6e-05 0.049263 4.2e-05 0.020968</velocity>
          <acceleration>0.759579 -1.8225 0.043392 -0.502886 0.114397 -2.77579</acceleration>
          <wrench>0.075958 -0.18225 0.004339 0 -0 0</wrench>
        </link>
        <link name='left_front_wheel'>
          <pose>0.081034 0.071164 0.034 1.3e-05 0.359217 -0.000627</pose>
          <velocity>0.000371 -0.00113 1.1e-05 0.033399 0.002656 0.02146</velocity>
          <acceleration>0.738649 -2.26011 0.022517 -2.30932 -0.783205 0.53035</acceleration>
          <wrench>0.073865 -0.226011 0.002252 0 -0 0</wrench>
        </link>
        <link name='left_rear_wheel'>
          <pose>-0.062965 0.071255 0.034 -1.2e-05 -0.062938 -0.000629</pose>
          <velocity>0.000371 -9.7e-05 1.6e-05 0.002811 0.012671 -0.004727</velocity>
          <acceleration>0.752749 -0.273114 0.053487 -2.97264 0.17785 2.94468</acceleration>
          <wrench>0.075275 -0.027311 0.005349 0 -0 0</wrench>
        </link>
        <link name='right_front_knuckle'>
          <pose>0.080935 -0.086836 0.033998 2.3e-05 3.2e-05 -0.000642</pose>
          <velocity>-0.000381 -0.00094 -4.2e-05 0.049624 4.3e-05 -0.021661</velocity>
          <acceleration>-0.773184 -1.82053 -0.093 -0.142423 0.115955 -1.42258</acceleration>
          <wrench>-0.077318 -0.182053 -0.0093 0 -0 0</wrench>
        </link>
        <link name='right_front_wheel'>
          <pose>0.080935 -0.086836 0.034 1.6e-05 0.41579 -0.000636</pose>
          <velocity>-0.000373 -0.001133 -3.9e-05 0.033521 -0.00292 -0.021147</velocity>
          <acceleration>-0.749218 -2.2675 -0.078869 -2.06161 0.639882 0.531759</acceleration>
          <wrench>-0.074922 -0.22675 -0.007887 0 -0 0</wrench>
        </link>
        <link name='right_rear_wheel'>
          <pose>-0.063065 -0.086745 0.034 9e-06 0.031272 -0.000634</pose>
          <velocity>-0.000372 -9.7e-05 -1.6e-05 0.002801 -0.012774 -0.004693</velocity>
          <acceleration>-0.764039 -0.27238 -0.056712 -2.98282 -0.135252 2.97876</acceleration>
          <wrench>-0.076404 -0.027238 -0.005671 0 -0 0</wrench>
        </link>
      </model>
      <light name='sun'>
        <pose>0 0 10 0 -0 0</pose>
      </light>
    </state>
    <gui fullscreen='0'>
      <camera name='user_camera'>
        <pose>-3.18499 -1.40854 2.64029 -0 0.539643 0.236194</pose>
        <view_controller>orbit</view_controller>
        <projection_type>perspective</projection_type>
      </camera>
    </gui>
  </world>
</sdf>
