<sdf version='1.7'>
  <world name='default'>
    <light name='sun' type='directional'>
      <cast_shadows>1</cast_shadows>
      <pose>0 0 10 0 -0 0</pose>
      <diffuse>0.8 0.8 0.8 1</diffuse>
      <specular>0.2 0.2 0.2 1</specular>
      <attenuation>
        <range>1000</range>
        <constant>0.9</constant>
        <linear>0.01</linear>
        <quadratic>0.001</quadratic>
      </attenuation>
      <direction>-0.5 0.1 -0.9</direction>
      <spot>
        <inner_angle>0</inner_angle>
        <outer_angle>0</outer_angle>
        <falloff>0</falloff>
      </spot>
    </light>
    <model name='ground_plane'>
      <static>1</static>
      <link name='link'>
        <collision name='collision'>
          <geometry>
            <plane>
              <normal>0 0 1</normal>
              <size>100 100</size>
            </plane>
          </geometry>
          <surface>
            <contact>
              <collide_bitmask>65535</collide_bitmask>
              <ode/>
            </contact>
            <friction>
              <ode>
                <mu>100</mu>
                <mu2>50</mu2>
              </ode>
              <torsional>
                <ode/>
              </torsional>
            </friction>
            <bounce/>
          </surface>
          <max_contacts>10</max_contacts>
        </collision>
        <visual name='visual'>
          <cast_shadows>0</cast_shadows>
          <geometry>
            <plane>
              <normal>0 0 1</normal>
              <size>100 100</size>
            </plane>
          </geometry>
          <material>
            <script>
              <uri>file://media/materials/scripts/gazebo.material</uri>
              <name>Gazebo/Grey</name>
            </script>
          </material>
        </visual>
        <self_collide>0</self_collide>
        <enable_wind>0</enable_wind>
        <kinematic>0</kinematic>
      </link>
    </model>
    <gravity>0 0 -9.8</gravity>
    <magnetic_field>6e-06 2.3e-05 -4.2e-05</magnetic_field>
    <atmosphere type='adiabatic'/>
    <physics type='ode'>
      <max_step_size>0.001</max_step_size>
      <real_time_factor>1</real_time_factor>
      <real_time_update_rate>1000</real_time_update_rate>
    </physics>
    <scene>
      <ambient>0.4 0.4 0.4 1</ambient>
      <background>0.7 0.7 0.7 1</background>
      <shadows>1</shadows>
    </scene>
    <audio>
      <device>default</device>
    </audio>
    <wind/>
    <spherical_coordinates>
      <surface_model>EARTH_WGS84</surface_model>
      <latitude_deg>0</latitude_deg>
      <longitude_deg>0</longitude_deg>
      <elevation>0</elevation>
      <heading_deg>0</heading_deg>
    </spherical_coordinates>
    <model name='wuyang_car'>
      <link name='base_footprint'>
        <inertial>
          <pose>0.005364 0 0.086409 0 -0 0</pose>
          <mass>3.3</mass>
          <inertia>
            <ixx>0.0101943</ixx>
            <ixy>0</ixy>
            <ixz>-0.00175391</ixz>
            <iyy>0.0256436</iyy>
            <iyz>0</iyz>
            <izz>0.0217774</izz>
          </inertia>
        </inertial>
        <collision name='base_footprint_fixed_joint_lump__base_link_collision'>
          <pose>0 0 0.0765 0 -0 0</pose>
          <geometry>
            <box>
              <size>0.265 0.11 0.123</size>
            </box>
          </geometry>
          <max_contacts>10</max_contacts>
          <surface>
            <contact>
              <ode/>
            </contact>
            <bounce/>
            <friction>
              <torsional>
                <ode/>
              </torsional>
              <ode/>
            </friction>
          </surface>
        </collision>
        <collision name='base_footprint_fixed_joint_lump__laser_link_collision_1'>
          <pose>0.059 0 0.1855 0 -0 0</pose>
          <geometry>
            <cylinder>
              <length>0.04</length>
              <radius>0.039</radius>
            </cylinder>
          </geometry>
          <surface>
            <contact>
              <ode/>
            </contact>
            <friction>
              <ode/>
              <torsional>
                <ode/>
              </torsional>
            </friction>
            <bounce/>
          </surface>
          <max_contacts>10</max_contacts>
        </collision>
        <visual name='base_footprint_fixed_joint_lump__RectangularPrism_visual'>
          <pose>0 0 0.0765 0 -0 0</pose>
          <geometry>
            <box>
              <size>0.265 0.11 0.123</size>
            </box>
          </geometry>
        </visual>
        <visual name='base_footprint_fixed_joint_lump__laser_link_visual_1'>
          <pose>0.059 0 0.1855 0 -0 0</pose>
          <geometry>
            <cylinder>
              <length>0.04</length>
              <radius>0.039</radius>
            </cylinder>
          </geometry>
        </visual>
        <sensor name='laserscan' type='ray'>
          <plugin name='laserscan' filename='libgazebo_ros_ray_sensor.so'>
            <ros>
              <namespace>/</namespace>
              <remapping>~/out:=scan</remapping>
            </ros>
            <output_type>sensor_msgs/LaserScan</output_type>
            <frame_name>laser_link</frame_name>
          </plugin>
          <always_on>1</always_on>
          <visualize>0</visualize>
          <update_rate>5</update_rate>
          <ray>
            <scan>
              <horizontal>
                <samples>1500</samples>
                <resolution>1</resolution>
                <min_angle>0</min_angle>
                <max_angle>6.28</max_angle>
              </horizontal>
              <vertical>
                <samples>1</samples>
                <min_angle>0</min_angle>
                <max_angle>0</max_angle>
              </vertical>
            </scan>
            <range>
              <min>0.12</min>
              <max>10</max>
              <resolution>0.015</resolution>
            </range>
            <noise>
              <type>gaussian</type>
              <mean>0</mean>
              <stddev>0.01</stddev>
            </noise>
          </ray>
          <pose>0.059 0 0.1855 0 -0 0</pose>
        </sensor>
        <self_collide>0</self_collide>
        <enable_wind>0</enable_wind>
        <kinematic>0</kinematic>
      </link>
      <joint name='camera_base_joint' type='revolute'>
        <pose relative_to='base_footprint'>0.1325 0 0.138 0 -0 0</pose>
        <parent>base_footprint</parent>
        <child>camera_pitch_link</child>
        <axis>
          <xyz>0 1 0</xyz>
          <limit>
            <lower>0</lower>
            <upper>0.7854</upper>
            <effort>1</effort>
            <velocity>1</velocity>
          </limit>
          <dynamics>
            <spring_reference>0</spring_reference>
            <spring_stiffness>0</spring_stiffness>
          </dynamics>
        </axis>
      </joint>
      <link name='camera_pitch_link'>
        <pose relative_to='camera_base_joint'>0 0 0 0 -0 0</pose>
        <inertial>
          <pose>-0.002833 0 0.003667 0 -0 0</pose>
          <mass>0.15</mass>
          <inertia>
            <ixx>7.10333e-05</ixx>
            <ixy>0</ixy>
            <ixz>3.11667e-06</ixz>
            <iyy>1.94417e-05</iyy>
            <iyz>0</iyz>
            <izz>6.84083e-05</izz>
          </inertia>
        </inertial>
        <collision name='camera_pitch_link_fixed_joint_lump__camera_body_link_collision'>
          <pose>-0.0085 0 0.011 0 -0 0</pose>
          <geometry>
            <box>
              <size>0.017 0.115 0.022</size>
            </box>
          </geometry>
          <surface>
            <contact>
              <ode/>
            </contact>
            <friction>
              <ode/>
              <torsional>
                <ode/>
              </torsional>
            </friction>
            <bounce/>
          </surface>
          <max_contacts>10</max_contacts>
        </collision>
        <visual name='camera_pitch_link_fixed_joint_lump__camera_body_link_visual'>
          <pose>-0.0085 0 0.011 0 -0 0</pose>
          <geometry>
            <box>
              <size>0.017 0.115 0.022</size>
            </box>
          </geometry>
        </visual>
        <sensor name='gemini_pro_sensor' type='depth'>
          <always_on>1</always_on>
          <update_rate>30</update_rate>
          <camera>
            <horizontal_fov>1.5708</horizontal_fov>
            <image>
              <width>800</width>
              <height>600</height>
              <format>R8G8B8</format>
            </image>
            <clip>
              <near>0.15</near>
              <far>10</far>
            </clip>
            <noise>
              <type>gaussian</type>
              <mean>0</mean>
              <stddev>0.007</stddev>
            </noise>
          </camera>
          <plugin name='gemini_camera_controller' filename='libgazebo_ros_camera.so'>
            <ros>
              <namespace>/</namespace>
              <remapping>~/image_raw:=image_raw</remapping>
              <remapping>~/camera_info:=camera_info</remapping>
              <remapping>~/depth/image_raw:=depth/image_raw</remapping>
              <remapping>~/depth/camera_info:=depth/camera_info</remapping>
              <remapping>~/points:=points</remapping>
            </ros>
            <camera_name>gemini_pro</camera_name>
            <frame_name>camera_optical_link</frame_name>
            <min_depth>0.15</min_depth>
            <max_depth>10.0</max_depth>
          </plugin>
          <pose>-0.0085 0 0.011 0 -0 0</pose>
        </sensor>
        <self_collide>0</self_collide>
        <enable_wind>0</enable_wind>
        <kinematic>0</kinematic>
      </link>
      <joint name='left_front_steering_joint' type='revolute'>
        <pose relative_to='base_footprint'>0.072 0.079 0.034 0 -0 0</pose>
        <parent>base_footprint</parent>
        <child>left_front_knuckle</child>
        <axis>
          <xyz>0 0 1</xyz>
          <limit>
            <lower>-0.6055</lower>
            <upper>0.6055</upper>
            <effort>10</effort>
            <velocity>10</velocity>
          </limit>
          <dynamics>
            <spring_reference>0</spring_reference>
            <spring_stiffness>0</spring_stiffness>
          </dynamics>
        </axis>
      </joint>
      <link name='left_front_knuckle'>
        <pose relative_to='left_front_steering_joint'>0 0 0 0 -0 0</pose>
        <inertial>
          <pose>0 0 0 0 -0 0</pose>
          <mass>0.1</mass>
          <inertia>
            <ixx>1e-05</ixx>
            <ixy>0</ixy>
            <ixz>0</ixz>
            <iyy>1e-05</iyy>
            <iyz>0</iyz>
            <izz>1e-05</izz>
          </inertia>
        </inertial>
        <self_collide>0</self_collide>
        <enable_wind>0</enable_wind>
        <kinematic>0</kinematic>
      </link>
      <joint name='left_front_rolling_joint' type='revolute'>
        <pose relative_to='left_front_knuckle'>0 0 0 0 -0 0</pose>
        <parent>left_front_knuckle</parent>
        <child>left_front_wheel</child>
        <axis>
          <xyz>0 1 0</xyz>
          <limit>
            <lower>-1e+16</lower>
            <upper>1e+16</upper>
          </limit>
          <dynamics>
            <spring_reference>0</spring_reference>
            <spring_stiffness>0</spring_stiffness>
          </dynamics>
        </axis>
      </joint>
      <link name='left_front_wheel'>
        <pose relative_to='left_front_rolling_joint'>0 0 0 0 -0 0</pose>
        <inertial>
          <pose>0 0 0 0 -0 0</pose>
          <mass>0.1</mass>
          <inertia>
            <ixx>0.0001</ixx>
            <ixy>0</ixy>
            <ixz>0</ixz>
            <iyy>0.0001</iyy>
            <iyz>0</iyz>
            <izz>0.0001</izz>
          </inertia>
        </inertial>
        <collision name='left_front_wheel_collision'>
          <pose>0 0 0 1.5708 -0 0</pose>
          <geometry>
            <cylinder>
              <length>0.026</length>
              <radius>0.034</radius>
            </cylinder>
          </geometry>
          <max_contacts>10</max_contacts>
          <surface>
            <contact>
              <ode/>
            </contact>
            <bounce/>
            <friction>
              <torsional>
                <ode/>
              </torsional>
              <ode/>
            </friction>
          </surface>
        </collision>
        <visual name='left_front_wheel_visual'>
          <pose>0 0 0 1.5708 -0 0</pose>
          <geometry>
            <cylinder>
              <length>0.026</length>
              <radius>0.034</radius>
            </cylinder>
          </geometry>
        </visual>
        <self_collide>0</self_collide>
        <enable_wind>0</enable_wind>
        <kinematic>0</kinematic>
      </link>
      <joint name='left_rear_rolling_joint' type='revolute'>
        <pose relative_to='base_footprint'>-0.072 0.079 0.034 0 -0 0</pose>
        <parent>base_footprint</parent>
        <child>left_rear_wheel</child>
        <axis>
          <xyz>0 1 0</xyz>
          <limit>
            <lower>-1e+16</lower>
            <upper>1e+16</upper>
          </limit>
          <dynamics>
            <spring_reference>0</spring_reference>
            <spring_stiffness>0</spring_stiffness>
          </dynamics>
        </axis>
      </joint>
      <link name='left_rear_wheel'>
        <pose relative_to='left_rear_rolling_joint'>0 0 0 0 -0 0</pose>
        <inertial>
          <pose>0 0 0 0 -0 0</pose>
          <mass>0.1</mass>
          <inertia>
            <ixx>0.0001</ixx>
            <ixy>0</ixy>
            <ixz>0</ixz>
            <iyy>0.0001</iyy>
            <iyz>0</iyz>
            <izz>0.0001</izz>
          </inertia>
        </inertial>
        <collision name='left_rear_wheel_collision'>
          <pose>0 0 0 1.5708 -0 0</pose>
          <geometry>
            <cylinder>
              <length>0.026</length>
              <radius>0.034</radius>
            </cylinder>
          </geometry>
          <max_contacts>10</max_contacts>
          <surface>
            <contact>
              <ode/>
            </contact>
            <bounce/>
            <friction>
              <torsional>
                <ode/>
              </torsional>
              <ode/>
            </friction>
          </surface>
        </collision>
        <visual name='left_rear_wheel_visual'>
          <pose>0 0 0 1.5708 -0 0</pose>
          <geometry>
            <cylinder>
              <length>0.026</length>
              <radius>0.034</radius>
            </cylinder>
          </geometry>
        </visual>
        <self_collide>0</self_collide>
        <enable_wind>0</enable_wind>
        <kinematic>0</kinematic>
      </link>
      <joint name='right_front_steering_joint' type='revolute'>
        <pose relative_to='base_footprint'>0.072 -0.079 0.034 0 -0 0</pose>
        <parent>base_footprint</parent>
        <child>right_front_knuckle</child>
        <axis>
          <xyz>0 0 1</xyz>
          <limit>
            <lower>-0.6055</lower>
            <upper>0.6055</upper>
            <effort>10</effort>
            <velocity>10</velocity>
          </limit>
          <dynamics>
            <spring_reference>0</spring_reference>
            <spring_stiffness>0</spring_stiffness>
          </dynamics>
        </axis>
      </joint>
      <link name='right_front_knuckle'>
        <pose relative_to='right_front_steering_joint'>0 0 0 0 -0 0</pose>
        <inertial>
          <pose>0 0 0 0 -0 0</pose>
          <mass>0.1</mass>
          <inertia>
            <ixx>1e-05</ixx>
            <ixy>0</ixy>
            <ixz>0</ixz>
            <iyy>1e-05</iyy>
            <iyz>0</iyz>
            <izz>1e-05</izz>
          </inertia>
        </inertial>
        <self_collide>0</self_collide>
        <enable_wind>0</enable_wind>
        <kinematic>0</kinematic>
      </link>
      <joint name='right_front_rolling_joint' type='revolute'>
        <pose relative_to='right_front_knuckle'>0 0 0 0 -0 0</pose>
        <parent>right_front_knuckle</parent>
        <child>right_front_wheel</child>
        <axis>
          <xyz>0 1 0</xyz>
          <limit>
            <lower>-1e+16</lower>
            <upper>1e+16</upper>
          </limit>
          <dynamics>
            <spring_reference>0</spring_reference>
            <spring_stiffness>0</spring_stiffness>
          </dynamics>
        </axis>
      </joint>
      <link name='right_front_wheel'>
        <pose relative_to='right_front_rolling_joint'>0 0 0 0 -0 0</pose>
        <inertial>
          <pose>0 0 0 0 -0 0</pose>
          <mass>0.1</mass>
          <inertia>
            <ixx>0.0001</ixx>
            <ixy>0</ixy>
            <ixz>0</ixz>
            <iyy>0.0001</iyy>
            <iyz>0</iyz>
            <izz>0.0001</izz>
          </inertia>
        </inertial>
        <collision name='right_front_wheel_collision'>
          <pose>0 0 0 1.5708 -0 0</pose>
          <geometry>
            <cylinder>
              <length>0.026</length>
              <radius>0.034</radius>
            </cylinder>
          </geometry>
          <max_contacts>10</max_contacts>
          <surface>
            <contact>
              <ode/>
            </contact>
            <bounce/>
            <friction>
              <torsional>
                <ode/>
              </torsional>
              <ode/>
            </friction>
          </surface>
        </collision>
        <visual name='right_front_wheel_visual'>
          <pose>0 0 0 1.5708 -0 0</pose>
          <geometry>
            <cylinder>
              <length>0.026</length>
              <radius>0.034</radius>
            </cylinder>
          </geometry>
        </visual>
        <self_collide>0</self_collide>
        <enable_wind>0</enable_wind>
        <kinematic>0</kinematic>
      </link>
      <joint name='right_rear_rolling_joint' type='revolute'>
        <pose relative_to='base_footprint'>-0.072 -0.079 0.034 0 -0 0</pose>
        <parent>base_footprint</parent>
        <child>right_rear_wheel</child>
        <axis>
          <xyz>0 1 0</xyz>
          <limit>
            <lower>-1e+16</lower>
            <upper>1e+16</upper>
          </limit>
          <dynamics>
            <spring_reference>0</spring_reference>
            <spring_stiffness>0</spring_stiffness>
          </dynamics>
        </axis>
      </joint>
      <link name='right_rear_wheel'>
        <pose relative_to='right_rear_rolling_joint'>0 0 0 0 -0 0</pose>
        <inertial>
          <pose>0 0 0 0 -0 0</pose>
          <mass>0.1</mass>
          <inertia>
            <ixx>0.0001</ixx>
            <ixy>0</ixy>
            <ixz>0</ixz>
            <iyy>0.0001</iyy>
            <iyz>0</iyz>
            <izz>0.0001</izz>
          </inertia>
        </inertial>
        <collision name='right_rear_wheel_collision'>
          <pose>0 0 0 1.5708 -0 0</pose>
          <geometry>
            <cylinder>
              <length>0.026</length>
              <radius>0.034</radius>
            </cylinder>
          </geometry>
          <max_contacts>10</max_contacts>
          <surface>
            <contact>
              <ode/>
            </contact>
            <bounce/>
            <friction>
              <torsional>
                <ode/>
              </torsional>
              <ode/>
            </friction>
          </surface>
        </collision>
        <visual name='right_rear_wheel_visual'>
          <pose>0 0 0 1.5708 -0 0</pose>
          <geometry>
            <cylinder>
              <length>0.026</length>
              <radius>0.034</radius>
            </cylinder>
          </geometry>
        </visual>
        <self_collide>0</self_collide>
        <enable_wind>0</enable_wind>
        <kinematic>0</kinematic>
      </link>
      <static>0</static>
      <plugin name='gazebo_ros2_control' filename='libgazebo_ros2_control.so'>
        <parameters>/home/hhz/wuyang_ws/install/wuyang_description/share/wuyang_description/config/ackermann_controller.yaml</parameters>
      </plugin>
      <pose>0 0 0.05 0 -0 0</pose>
    </model>
    <state world_name='default'>
      <sim_time>1424 587000000</sim_time>
      <real_time>321 260460208</real_time>
      <wall_time>1783835756 460176924</wall_time>
      <iterations>314453</iterations>
      <model name='ground_plane'>
        <pose>0 0 0 0 -0 0</pose>
        <scale>1 1 1</scale>
        <link name='link'>
          <pose>0 0 0 0 -0 0</pose>
          <velocity>0 0 0 0 -0 0</velocity>
          <acceleration>0 0 0 0 -0 0</acceleration>
          <wrench>0 0 0 0 -0 0</wrench>
        </link>
      </model>
      <model name='sandbox_map'>
        <pose>0.224851 0.073986 0 0 -0 0</pose>
        <scale>1 1 1</scale>
        <link name='link'>
          <pose>0.224851 0.073986 0 0 -0 0</pose>
          <velocity>0 0 0 0 -0 0</velocity>
          <acceleration>0 0 0 0 -0 0</acceleration>
          <wrench>0 0 0 0 -0 0</wrench>
        </link>
      </model>
      <model name='wuyang_car'>
        <pose>0.778503 0.626787 0.000494 -5.2e-05 2e-05 -1.5621</pose>
        <scale>1 1 1</scale>
        <link name='base_footprint'>
          <pose>0.778503 0.626787 0.000494 -5.2e-05 2e-05 -1.5621</pose>
          <velocity>-0.003754 -0.002347 -0.004716 -0.027358 0.064535 0.002029</velocity>
          <acceleration>1.34939 0.267106 -5.03892 2.84987 -0.88516 -2.43619</acceleration>
          <wrench>4.45299 0.88145 -16.6284 0 -0 0</wrench>
        </link>
        <link name='camera_pitch_link'>
          <pose>0.779663 0.49429 0.138492 -5.2e-05 -7e-05 -1.5621</pose>
          <velocity>0.005429 0.001429 -0.001173 -0.004766 0.064821 0.001996</velocity>
          <acceleration>6.06772 2.35266 -0.5146 2.14191 -0.512424 1.83266</acceleration>
          <wrench>0.910158 0.352899 -0.07719 0 -0 0</wrench>
        </link>
        <link name='left_front_knuckle'>
          <pose>0.858127 0.555477 0.034491 -8e-05 2e-05 -1.56212</pose>
          <velocity>-0.001267 -0.001268 -0.008387 -0.027236 0.055829 0.000652</velocity>
          <acceleration>-3.03231 -1.73419 -9.89731 -2.71554 1.27486 1.3999</acceleration>
          <wrench>-0.303231 -0.173419 -0.989731 0 -0 0</wrench>
        </link>
        <link name='left_front_wheel'>
          <pose>0.858126 0.555477 0.034492 -3.14149 -0.271157 1.57944</pose>
          <velocity>-0.000985 -0.001273 -0.008722 -0.013852 0.051623 0.000796</velocity>
          <acceleration>-2.29933 -1.74175 -12.1578 -0.112598 0.41286 0.175224</acceleration>
          <wrench>-0.229933 -0.174175 -1.21578 0 -0 0</wrench>
        </link>
        <link name='left_rear_wheel'>
          <pose>0.856874 0.699471 0.034492 -8.1e-05 -0.139928 -1.56208</pose>
          <velocity>-0.00144 -0.001268 -0.011767 0.009349 0.057648 0.002102</velocity>
          <acceleration>-2.8602 -1.73177 -14.6952 2.45366 -0.544166 2.84976</acceleration>
          <wrench>-0.28602 -0.173177 -1.46952 0 -0 0</wrench>
        </link>
        <link name='right_front_knuckle'>
          <pose>0.700135 0.554102 0.034499 1.8e-05 2e-05 -1.56209</pose>
          <velocity>-0.001054 -0.001579 0.002412 -0.026755 -0.01594 0.000369</velocity>
          <acceleration>-2.82228 -1.66715 4.3022 0.907193 -0.787951 -2.02418</acceleration>
          <wrench>-0.282228 -0.166715 0.430221 0 -0 0</wrench>
        </link>
        <link name='right_front_wheel'>
          <pose>0.700136 0.554102 0.0345 3.14103 -1.52182 1.58006</pose>
          <velocity>-0.000418 -0.001569 0.002447 0.046158 -0.012271 0.000225</velocity>
          <acceleration>-1.92539 -1.64599 5.1047 -1.3995 -0.077944 1.03207</acceleration>
          <wrench>-0.192539 -0.164599 0.51047 0 -0 0</wrench>
        </link>
        <link name='right_rear_wheel'>
          <pose>0.698882 0.698097 0.0345 -2.9e-05 0.000838 -1.5621</pose>
          <velocity>-0.001858 -0.001603 -0.001488 0.009238 0.070421 0.002236</velocity>
          <acceleration>-3.28148 -1.68844 -1.01638 2.34269 -0.750703 2.98392</acceleration>
          <wrench>-0.328148 -0.168844 -0.101638 0 -0 0</wrench>
        </link>
      </model>
      <light name='sun'>
        <pose>0 0 10 0 -0 0</pose>
      </light>
    </state>
    <gui fullscreen='0'>
      <camera name='user_camera'>
        <pose>-0.029 0.227924 2.4802 -2.9e-05 1.5698 -0.683861</pose>
        <view_controller>orbit</view_controller>
        <projection_type>perspective</projection_type>
      </camera>
    </gui>
    <model name='sandbox_map'>
      <static>1</static>
      <link name='link'>
        <collision name='collision'>
          <geometry>
            <box>
              <size>3.2 3.5 0.001</size>
            </box>
          </geometry>
          <surface>
            <friction>
              <ode>
                <mu>1</mu>
                <mu2>1</mu2>
              </ode>
              <torsional>
                <ode/>
              </torsional>
            </friction>
            <contact>
              <ode/>
            </contact>
            <bounce/>
          </surface>
          <max_contacts>10</max_contacts>
        </collision>
        <visual name='visual'>
          <cast_shadows>0</cast_shadows>
          <geometry>
            <box>
              <size>3.2 3.5 0.001</size>
            </box>
          </geometry>
          <material>
            <script>
              <uri>model://sandbox_map/materials/scripts</uri>
              <uri>model://sandbox_map/materials/textures</uri>
              <name>SandBoxMap/Diffuse</name>
            </script>
          </material>
        </visual>
        <self_collide>0</self_collide>
        <enable_wind>0</enable_wind>
        <kinematic>0</kinematic>
      </link>
      <pose>0.236314 0.052298 0 0 -0 0</pose>
    </model>
  </world>
</sdf>
